
INFO:root:load_data. dataset_name = mnist
server started. Listening on port 50000
done running
 * Serving Flask app "app" (lazy loading)
 * Environment: production
[31m   WARNING: This is a development server. Do not use it in a production deployment.
   Use a production WSGI server instead.
 * Debug mode: off
INFO:root:create_model. model_name = lr, output_dim = 10
INFO:root:/home/cbq/sourcecode/FedML-IoT
E1025 23:10:40.259009200    7769 socket_utils_common_posix.cc:223] check for SO_REUSEPORT: {"created":"@1635174640.258991800","description":"Protocol not available","errno":92,"file":"src/core/lib/iomgr/socket_utils_common_posix.cc","file_line":202,"os_error":"Protocol not available","syscall":"getsockopt(SO_REUSEPORT)"}
INFO:werkzeug: * Running on http://0.0.0.0:5000/ (Press CTRL+C to quit)
INFO:werkzeug:127.0.0.1 - - [25/Oct/2021 23:11:04] "[37mPOST /api/register?device_id=0 HTTP/1.1[39m" 200 -
ERROR:app:Exception on /get-preprocessed-data/0 [GET]
Traceback (most recent call last):
  File "/usr/local/lib/python3.8/dist-packages/flask/app.py", line 2447, in wsgi_app
    response = self.full_dispatch_request()
  File "/usr/local/lib/python3.8/dist-packages/flask/app.py", line 1952, in full_dispatch_request
    rv = self.handle_user_exception(e)
  File "/usr/local/lib/python3.8/dist-packages/flask/app.py", line 1821, in handle_user_exception
    reraise(exc_type, exc_value, tb)
  File "/usr/local/lib/python3.8/dist-packages/flask/_compat.py", line 39, in reraise
    raise value
  File "/usr/local/lib/python3.8/dist-packages/flask/app.py", line 1950, in full_dispatch_request
    rv = self.dispatch_request()
  File "/usr/local/lib/python3.8/dist-packages/flask/app.py", line 1936, in dispatch_request
    return self.view_functions[rule.endpoint](**req.view_args)
  File "/home/cbq/sourcecode/FedML-IoT/FedML/fedml_server/FedML-Server/executor/app.py", line 119, in get_preprocessed_data
    raise
RuntimeError: No active exception to reraise
